<?xml version="1.0"?>
<robot name="robot">

    <material name="red">
        <color rgba="0.9 0 0 1.0" />
    </material>
    <material name="black">
        <color rgba="0.3 0.3 0.3 1.0" />
    </material>


    <link name="corpus">
        <visual>
            <origin xyz="0 0 0" rpy="0 0 0" />
            <geometry>
                <mesh filename="../mesh/Corpus.stl" scale="0.01 0.01 0.01"/>
            </geometry>
            <material name="red"/>
        </visual>
        <collision>
            <origin xyz="0 0 0" rpy="0 0 0" />
            <geometry>
                <!-- <box size="1.31 1.46 0.6305"/> -->
                <mesh filename="../mesh/Corpus.stl" scale="0.01 0.01 0.01"/>
            </geometry>
        </collision>
        <inertial>
            <origin xyz="0 -0.1 -0.1" rpy="0 0 0" />
            <mass value="561"/>
            <inertia ixx="116.6" ixy="-1.1" ixz="-0.05" iyy="102.5" iyz="4.0" izz="198.5"/>
        </inertial>
         <contact> 
            <lateral_friction value="1"/>
        </contact>
    </link>

    <link name="upper_leg_front_left">
        <visual>
            <origin xyz="0.08 0.295 0" rpy="3.1415 0 0" />
            <geometry>
                <mesh filename="../mesh/UpperLegL.stl" scale="0.01 0.01 0.01"/>
            </geometry>
            <material name="black"/>
        </visual>
        <collision>
            <origin xyz="0.08 0.295 0" rpy="3.1415 0 0" />
            <geometry>
                <!-- <box size="0.42 0.85 0.42"/> -->
                <mesh filename="../mesh/UpperLegL.stl" scale="0.01 0.01 0.01"/>
            </geometry>
        </collision>
        <inertial>
            <mass value="22"/>
            <origin xyz="0.08 0.295 0" rpy="3.1415 0 0" />
            <inertia ixx="10.9" ixy="-3.2" ixz="-1.9" iyy="7.9" iyz="-3.2" izz="10.9"/>
        </inertial>
         <contact> 
            <lateral_friction value="1"/>
        </contact>
    </link>

    <link name="upper_leg_rear_left">
        <visual>
            <origin xyz="0.08 -0.295 0" rpy="3.1415 0 0" />
            <geometry>
                <mesh filename="../mesh/UpperLegR.stl" scale="0.01 0.01 0.01"/>
            </geometry>
            <material name="black"/>
        </visual>
        <collision>
            <origin xyz="0.08 -0.295 0" rpy="3.1415 0 0" />
            <geometry>
                <!-- <box size="0.42 0.85 0.42"/> -->
                <mesh filename="../mesh/UpperLegR.stl" scale="0.01 0.01 0.01"/>
            </geometry>
        </collision>
        <inertial>
            <origin xyz="0.08 -0.295 0" rpy="3.1415 0 0" />
            <mass value="22"/>
            <inertia ixx="10.9" ixy="-3.2" ixz="-1.9" iyy="7.9" iyz="-3.2" izz="10.9"/>
        </inertial>
         <contact> 
            <lateral_friction value="1"/>
        </contact>
    </link>

    <link name="upper_leg_front_right">
        <visual>
            <origin xyz="-0.08 0.295 0" rpy="0 3.1415 0" />
            <geometry>
                <mesh filename="../mesh/UpperLegR.stl" scale="0.01 0.01 0.01"/>
            </geometry>
            <material name="black"/>
        </visual>
        <collision>
            <origin xyz="-0.08 0.295 0" rpy="0 3.1415 0" />
            <geometry>
                <!-- <box size="0.42 0.85 0.42"/> -->
                <mesh filename="../mesh/UpperLegR.stl" scale="0.01 0.01 0.01"/>
            </geometry>
        </collision>
        <inertial>
            <origin xyz="-0.08 0.295 0" rpy="0 3.1415 0" />
            <mass value="22"/>
            <inertia ixx="10.9" ixy="-3.2" ixz="-1.9" iyy="7.9" iyz="-3.2" izz="10.9"/>
        </inertial>
         <contact> 
            <lateral_friction value="1"/>
        </contact>
    </link>

    <link name="upper_leg_rear_right">
        <visual>
            <origin xyz="-0.08 -0.295 0" rpy="0 3.1415 0" />
            <geometry>
                <mesh filename="../mesh/UpperLegL.stl" scale="0.01 0.01 0.01"/>
            </geometry>
            <material name="black"/>
        </visual>
        <collision>
            <origin xyz="-0.08 -0.295 0" rpy="0 3.1415 0" />
            <geometry>
                <!-- <box size="0.42 0.85 0.42"/> -->
                <mesh filename="../mesh/UpperLegL.stl" scale="0.01 0.01 0.01"/>
            </geometry>
        </collision>
        <inertial>
            <origin xyz="-0.08 -0.295 0" rpy="0 3.1415 0" />
            <mass value="22"/>
            <inertia ixx="10.9" ixy="-3.2" ixz="-1.9" iyy="7.9" iyz="-3.2" izz="10.9"/>

        </inertial>
         <contact> 
            <lateral_friction value="1"/>
        </contact>
    </link>

    <link name="foot_front_left">
       
        <visual>
            <origin xyz="0 0.471 0" rpy="3.14 0 1.57" />
            <geometry>
                <mesh filename="../mesh/FootL.stl" scale="0.01 0.01 0.01"/>
            </geometry>
            <material name="red"/>
        </visual>
        <collision>
            <origin xyz="0 0.471 0" rpy="3.14 0 1.57" />
            <geometry>
                <mesh filename="../mesh/FootL.stl" scale="0.01 0.01 0.01"/>
            </geometry>
        </collision>
        <inertial>
            <origin xyz="0 0.21 0" rpy="3.14 0 1.57" />
            <mass value="72"/>
            <inertia ixx="0.96" ixy="-0.58" ixz="-0.09" iyy="10.9" iyz="-0.07" izz="11.3"/>
        </inertial>
         <contact> 
            <lateral_friction value="1"/>
        </contact>
    </link>

    <link name="foot_rear_left">
       
        <visual>
            <origin xyz="0 -0.471 0" rpy="3.14 0 -1.57" />
            <geometry>
                <mesh filename="../mesh/FootR.stl" scale="0.01 0.01 0.01"/>
            </geometry>
            <material name="red"/>
        </visual>
        <collision>
            <origin xyz="0 -0.471 0" rpy="3.14 0 -1.57" />
            <geometry>
                <mesh filename="../mesh/FootR.stl" scale="0.01 0.01 0.01"/>
            </geometry>
        </collision>
        <inertial>
            <origin xyz="0 -0.21 0" rpy="3.14 0 -1.57" />
            <mass value="72"/>
            <inertia ixx="0.96" ixy="-0.58" ixz="-0.09" iyy="10.9" iyz="-0.07" izz="11.3"/>
        </inertial>
         <contact> 
            <lateral_friction value="1"/>
        </contact>
    </link>

    <link name="foot_front_right">
       
        <visual>
            <origin xyz="0 0.471 0" rpy="3.14 0 1.57" />
            <geometry>
                <mesh filename="../mesh/FootR.stl" scale="0.01 0.01 0.01"/>
            </geometry>
            <material name="red"/>
        </visual>
        <collision>
            <origin xyz="0 0.471 0" rpy="3.14 0 1.57" />
            <geometry>
                <mesh filename="../mesh/FootR.stl" scale="0.01 0.01 0.01"/>
            </geometry>
        </collision>
        <inertial>
            <origin xyz="0 0.21 0" rpy="3.14 0 1.57" />
            <mass value="72"/>
            <inertia ixx="0.96" ixy="-0.58" ixz="-0.09" iyy="10.9" iyz="-0.07" izz="11.3"/>
        </inertial>
         <contact> 
            <lateral_friction value="1"/>
        </contact>
    </link>

    <link name="foot_rear_right">
       
        <visual>
            <origin xyz="0 -0.471 0" rpy="3.14 0 -1.57" />
            <geometry>
                <mesh filename="../mesh/FootL.stl" scale="0.01 0.01 0.01"/>
            </geometry>
            <material name="red"/>
        </visual>
        <collision>
            <origin xyz="0 -0.471 0" rpy="3.14 0 1.57" />
            <geometry>
                <mesh filename="../mesh/FootL.stl" scale="0.01 0.01 0.01"/>
            </geometry>
        </collision>
        <inertial>
            <origin xyz="0 -0.21 0" rpy="3.14 0 -1.57" />
            <mass value="72"/>
            <inertia ixx="0.96" ixy="-0.58" ixz="-0.09" iyy="10.9" iyz="-0.07" izz="11.3"/>
        </inertial>
         <contact> 
            <lateral_friction value="1"/>
        </contact>
    </link>


    <joint name="corpus_to_upper_fl" type="revolute">
        <parent link="corpus"/>
        <child link="upper_leg_front_left"/>
        <origin xyz="-0.55 0.55 0"/>
        <axis xyz="0 0 1"/>
        <limit effort="93000" lower="-0.2" upper="2.4" velocity="5.1"/>
    </joint>

    <joint name="corpus_to_upper_rl" type="revolute">
        <parent link="corpus"/>
        <child link="upper_leg_rear_left"/>
        <origin xyz="-0.55 -0.55 0"/>
        <axis xyz="0 0 1"/>
        <limit effort="93000" lower="-2.4" upper="0.2" velocity="5.1"/>
    </joint>

    <joint name="corpus_to_upper_fr" type="revolute">
        <parent link="corpus"/>
        <child link="upper_leg_front_right"/>
        <origin xyz="0.55 0.55 0"/>
        <axis xyz="0 0 1"/>
        <limit effort="93000" lower="-2.4" upper="0.2" velocity="5.1"/>
    </joint>

    <joint name="corpus_to_upper_rr" type="revolute">
        <parent link="corpus"/>
        <child link="upper_leg_rear_right"/>
        <origin xyz="0.55 -0.55 0"/>
        <axis xyz="0 0 1"/>
        <limit effort="93000" lower="-0.2" upper="2.4" velocity="5.1"/>
    </joint>

    <joint name="upper_leg_to_foot_fl" type="revolute">
        <parent link="upper_leg_front_left"/>
        <child link="foot_front_left"/>
        <origin xyz="-0.02 0.59 -0.08"/>
        <axis xyz="1 0 0"/>
        <limit effort="93000" lower="-2.2" upper="1.9" velocity="5.1"/>
    </joint>

    <joint name="upper_leg_to_foot_rl" type="revolute">
        <parent link="upper_leg_rear_left"/>
        <child link="foot_rear_left"/>
        <origin xyz="-0.02 -0.59 -0.08"/>
        <axis xyz="1 0 0"/>
        <limit effort="93000" lower="-1.9" upper="2.2" velocity="5.1"/>
    </joint>

    <joint name="upper_leg_to_foot_fr" type="revolute">
        <parent link="upper_leg_front_right"/>
        <child link="foot_front_right"/>
        <origin xyz="0.02 0.59 -0.08"/>
        <axis xyz="1 0 0"/>
        <limit effort="93000" lower="-2.2" upper="1.9" velocity="5.1"/>
    </joint>

    <joint name="upper_leg_to_foot_rr" type="revolute">
        <parent link="upper_leg_rear_right"/>
        <child link="foot_rear_right"/>
        <origin xyz="0.02 -0.59 -0.08"/>
        <axis xyz="1 0 0"/>
        <limit effort="93000" lower="-1.9" upper="2.2" velocity="5.1"/>
    </joint>


</robot>